[2025-07-23T11:56:02.348+0000] {taskinstance.py:1957} INFO - Dependencies all met for dep_context=non-requeueable deps ti=<TaskInstance: etl_script_dag.run_etl scheduled__2025-07-22T00:00:00+00:00 [queued]>
[2025-07-23T11:56:02.359+0000] {taskinstance.py:1957} INFO - Dependencies all met for dep_context=requeueable deps ti=<TaskInstance: etl_script_dag.run_etl scheduled__2025-07-22T00:00:00+00:00 [queued]>
[2025-07-23T11:56:02.359+0000] {taskinstance.py:2171} INFO - Starting attempt 1 of 2
[2025-07-23T11:56:02.379+0000] {taskinstance.py:2192} INFO - Executing <Task(BashOperator): run_etl> on 2025-07-22 00:00:00+00:00
[2025-07-23T11:56:02.391+0000] {standard_task_runner.py:60} INFO - Started process 189 to run task
[2025-07-23T11:56:02.395+0000] {standard_task_runner.py:87} INFO - Running: ['***', 'tasks', 'run', 'etl_script_dag', 'run_etl', 'scheduled__2025-07-22T00:00:00+00:00', '--job-id', '4', '--raw', '--subdir', 'DAGS_FOLDER/etl_dag.py', '--cfg-path', '/tmp/tmpif20vhyl']
[2025-07-23T11:56:02.398+0000] {standard_task_runner.py:88} INFO - Job 4: Subtask run_etl
[2025-07-23T11:56:02.440+0000] {logging_mixin.py:188} WARNING - /home/***/.local/lib/python3.10/site-packages/***/settings.py:195 DeprecationWarning: The sql_alchemy_conn option in [core] has been moved to the sql_alchemy_conn option in [database] - the old setting has been used, but please update your config.
[2025-07-23T11:56:02.516+0000] {task_command.py:423} INFO - Running <TaskInstance: etl_script_dag.run_etl scheduled__2025-07-22T00:00:00+00:00 [running]> on host e9cde7c6c5cb
[2025-07-23T11:56:02.749+0000] {taskinstance.py:2481} INFO - Exporting env vars: AIRFLOW_CTX_DAG_OWNER='inoth' AIRFLOW_CTX_DAG_ID='etl_script_dag' AIRFLOW_CTX_TASK_ID='run_etl' AIRFLOW_CTX_EXECUTION_DATE='2025-07-22T00:00:00+00:00' AIRFLOW_CTX_TRY_NUMBER='1' AIRFLOW_CTX_DAG_RUN_ID='scheduled__2025-07-22T00:00:00+00:00'
[2025-07-23T11:56:02.798+0000] {subprocess.py:63} INFO - Tmp dir root location: /tmp
[2025-07-23T11:56:02.799+0000] {subprocess.py:75} INFO - Running command: ['/usr/bin/bash', '-c', 'docker exec dataextract_etl-app_1 python /app/app.py']
[2025-07-23T11:56:02.823+0000] {subprocess.py:86} INFO - Output:
[2025-07-23T11:56:03.211+0000] {subprocess.py:93} INFO - Cannot connect to the Docker daemon at unix:///var/run/docker.sock. Is the docker daemon running?
[2025-07-23T11:56:03.212+0000] {subprocess.py:97} INFO - Command exited with return code 1
[2025-07-23T11:56:03.226+0000] {taskinstance.py:2699} ERROR - Task failed with exception
Traceback (most recent call last):
  File "/home/airflow/.local/lib/python3.10/site-packages/airflow/models/taskinstance.py", line 433, in _execute_task
    result = execute_callable(context=context, **execute_callable_kwargs)
  File "/home/airflow/.local/lib/python3.10/site-packages/airflow/operators/bash.py", line 212, in execute
    raise AirflowException(
airflow.exceptions.AirflowException: Bash command failed. The command returned a non-zero exit code 1.
[2025-07-23T11:56:03.243+0000] {taskinstance.py:1138} INFO - Marking task as UP_FOR_RETRY. dag_id=etl_script_dag, task_id=run_etl, execution_date=20250722T000000, start_date=20250723T115602, end_date=20250723T115603
[2025-07-23T11:56:03.278+0000] {standard_task_runner.py:107} ERROR - Failed to execute job 4 for task run_etl (Bash command failed. The command returned a non-zero exit code 1.; 189)
[2025-07-23T11:56:03.295+0000] {local_task_job_runner.py:234} INFO - Task exited with return code 1
[2025-07-23T11:56:03.333+0000] {taskinstance.py:3281} INFO - 0 downstream tasks scheduled from follow-on schedule check
